<?xml version="1.0"?>
<robot xmlns:xacro="http://www.ros.org/wiki/xacro" name="yttrium">

<xacro:property name="control_config"   value="$(find yttrium_description)/config/diff_drive_control.yaml" />

<xacro:property name="c_orange" value="1 0.647 0 1"/>
<xacro:property name="c_black" value="0 0 0 1"/>
<xacro:property name="wheel_separation" value="0.26" />

<xacro:property name="c_white" value="1 1 1 1"/>
<xacro:property name="c_yellow" value="1 1 0 1"/>
<xacro:property name="c_blue" value="0 0 1 1"/>

<xacro:property name="wheel_radius" value="0.04" />


  <link name="base_footprint"/>

  <!-- Base Link -->
  <link name="base_link">
    <visual>
      <geometry>
        <cylinder length="0.08" radius="0.175"/>
      </geometry>
      
      <material name="white">
        <color rgba="${c_white}"/>
      </material>
    </visual>
    <inertial>
      <mass value="4.2"/>
      <origin xyz="0 0 0"/>
      <inertia ixx="0.164" ixy="0" ixz="0" iyy="0.164" iyz="0" izz="0.025"/>
    </inertial>
    <collision>
      <geometry>
        <cylinder length="0.08" radius="0.175"/>
      </geometry>
    </collision>
  </link>

  <!-- IMU -->
  <link name="imu">
    <visual>
      <geometry>
        <box size="0.035 0.035 0.035"/>
      </geometry>
    </visual>
  </link>

  <joint name="imu_joint" type="fixed">
    <parent link="base_link"/>
    <child link="imu"/>
  </joint>

  <!-- Depth Camera -->
  <link name="camera_link">
    <visual>
      <geometry>
        <box size="0.02 0.016 0.08"/>
      </geometry>
    </visual>
    <inertial>
      <mass value="0.08"/>
      <origin xyz="0 0 0"/>
      <inertia ixx="0.000224" ixy="0" ixz="0" iyy="0.000256" iyz="0" izz="0.000032"/>
    </inertial>
    <collision>
      <geometry>
        <box size="0.02 0.016 0.08"/>
      </geometry>
    </collision>
  </link>

  <joint name="depth_camera_joint" type="fixed">
    <parent link="base_link"/>
    <child link="camera_link"/>
    <origin xyz="0.165 0 0" rpy="-1.5708 0 0"/>
  </joint>

  <!-- Empty Link for Depth Camera -->
  <link name = "optical_link">
  </link>

   <joint name="optical_depth_camera_joint" type="fixed">
    <parent link="camera_link"/>
    <child link="optical_link"/>
    <origin xyz="0.02 0 0" rpy="0 0 0"/>
  </joint>

  <!-- Lidar -->
  <link name="lidar_link">
    <visual>
      <geometry>
        <cylinder length="0.03" radius="0.035"/>
      </geometry>
      <material name="black">
        <color rgba="${c_black}"/>
      </material>
    </visual>
    <inertial>
      <mass value="0.20"/>
      <origin xyz="0 0 0"/>
      <inertia ixx="0.001225" ixy="0" ixz="0" iyy="0.001225" iyz="0" izz="0.0006125"/>
    </inertial>
    <collision>
      <geometry>
        <cylinder length="0.03" radius="0.035"/>
      </geometry>
    </collision>
  </link>
  <joint name="lidar_joint" type="fixed">
    <parent link="base_link"/>
    <child link="lidar_link"/>
    <origin xyz="0.075 0 0.055" rpy="0 0 0"/>
  </joint>
  <!-- Left Wheel -->
  <link name="wheel_left">
    <inertial>
      <mass value="0.05"/>
      <origin xyz="0 0 0"/>
      <inertia ixx="0.0004" ixy="0" ixz="0" iyy="0.0004" iyz="0" izz="0.0002"/>
    </inertial>
    <collision>
      <geometry>
        <cylinder length="0.02" radius="0.04"/>
      </geometry>
    </collision>
    <visual>
      <geometry>
        <cylinder length="0.02" radius="0.04"/>
      </geometry>
      <origin rpy="0 0 0" xyz="0 0 0"/>
      <material name="yellow">
        <color rgba="${c_yellow}"/>
      </material>
    </visual>
  </link>

  <joint name="base_to_wheel_left" type="continuous">
    <parent link="base_link"/>
    <child link="wheel_left"/>
    <origin xyz="0 0.13 -0.005" rpy="-1.5708 0 0"/>
    <axis xyz="0 0 1"/>
  </joint>

  <!-- Right Wheel -->
  <link name="wheel_right">
    <inertial>
      <mass value="0.05"/>
      <origin xyz="0 0 0"/>
      <inertia ixx="0.0004" ixy="0" ixz="0" iyy="0.0004" iyz="0" izz="0.0002"/>
    </inertial>
    <collision>
      <geometry>
        <cylinder length="0.02" radius="0.04"/>
      </geometry>
    </collision>
    <visual>
      <geometry>
        <cylinder length="0.02" radius="0.04"/>
      </geometry>
      <origin rpy="0 0 0" xyz="0 0 0"/>
      <material name="yellow">
        <color rgba="${c_yellow}"/>
      </material>
    </visual>
  </link>

  <joint name="base_to_wheel_right" type="continuous">
    <parent link="base_link"/>
    <child link="wheel_right"/>
    <origin xyz="0 -0.13 -0.005" rpy="-1.5708 0 0"/>
    <axis xyz="0 0 1"/>
  </joint>

  <!-- Ball Caster -->
  <link name="front_ball_caster">
    <inertial>
      <mass value="0.03"/>
      <origin xyz="0 0 0"/>
      <inertia ixx="0.0000024" ixy="0" ixz="0" iyy="0.0000024" iyz="0" izz="0.0000024"/>
    </inertial>
    <collision>
      <geometry>
        <sphere radius="0.01"/>
      </geometry>
    </collision>
    <visual>
      <geometry>
        <sphere radius="0.01"/>
      </geometry>
      <material name="blue">
        <color rgba="${c_blue}"/>
      </material>
    </visual>
  </link>

  <joint name="front_ball_joint" type="fixed">
    <parent link="base_link"/>
    <child link="front_ball_caster"/>
    <origin xyz="0.145 0 -0.035" rpy="0 0 0"/>
  </joint>

  <link name="back_ball_caster">
    <inertial>
      <mass value="0.03"/>
      <origin xyz="0 0 0"/>
      <inertia ixx="0.0000024" ixy="0" ixz="0" iyy="0.0000024" iyz="0" izz="0.0000024"/>
    </inertial>
    <collision>
      <geometry>
        <sphere radius="0.01"/>
      </geometry>
    </collision>
    <visual>
      <geometry>
        <sphere radius="0.01"/>
      </geometry>
      <material name="orange">
        <color rgba="${c_orange}"/>
      </material>
    </visual>
  </link>

  <joint name="back_ball_joint" type="fixed">
    <parent link="base_link"/>
    <child link="back_ball_caster"/>
    <origin xyz="-0.145 0 -0.035" rpy="0 0 0"/>
  </joint>


  <joint name="base_footprint_joint" type="fixed">
    <parent link="base_footprint"/>
    <child link="base_link"/>
    <origin xyz="0 0 0.045" rpy="0 0 0"/>
  </joint>



<!-- GAZEBO PLUGINS -->
  <!-- Differential Drive - https://gazebosim.org/api/gazebo/4.5/classignition_1_1gazebo_1_1systems_1_1DiffDrive.html -->
  <gazebo>
    <plugin filename="ignition-gazebo-diff-drive-system" name="ignition::gazebo::systems::DiffDrive">
      <!-- Wheel Joints -->
      <left_joint>base_to_wheel_left</left_joint>
      <right_joint>base_to_wheel_right</right_joint>

      <!-- Kinematics -->
      <wheel_separation>${wheel_separation}</wheel_separation>
      <wheel_radius>${wheel_radius}</wheel_radius>

      <odom_publish_frequency>50</odom_publish_frequency>
      
      <!-- TF Frames -->
      <frame_id>/odom</frame_id>
      <child_frame_id>/base_footprint</child_frame_id>
    </plugin>
  </gazebo>

  <gazebo>
      <plugin filename="ignition-gazebo-joint-state-publisher-system" name="ignition::gazebo::systems::JointStatePublisher">
        <update_rate>50</update_rate>
        <joint_name>base_to_wheel_left</joint_name>
        <joint_name>base_to_wheel_right</joint_name>
      </plugin>
  </gazebo>


  <gazebo reference="wheel_right">
    <mu1 value="1.0"/>
    <mu2 value="1.0"/>

  </gazebo>

  <gazebo reference="wheel_left">
    <mu1 value="1.0"/>
    <mu2 value="1.0"/>
  </gazebo>

  <gazebo reference="lidar_link">
    <sensor type="gpu_lidar" name="generic_lidar_sensor">

      <topic>/model/gz_example_robot/scan</topic>
      <frame_id>laser</frame_id>
      <ignition_frame_id>laser</ignition_frame_id>

      <update_rate>10.0</update_rate>
      <ray>
        <scan>
          <horizontal>
            <samples>1024</samples>
            <resolution>1</resolution>
            <min_angle>-${pi*0.75}</min_angle>
            <max_angle>${pi*0.75}</max_angle>
          </horizontal>
        </scan>
        <range>
          <min>0.20</min>
          <max>20.0</max>
          <resolution>0.03</resolution>
        </range>
        <noise>
          <type>gaussian</type>
          <mean>0.0</mean>
          <stddev>0.001</stddev>
        </noise>
      </ray>
      <always_on>1</always_on>
      <visualize>true</visualize>
    </sensor>
  </gazebo>
  <gazebo>
    <plugin filename="libignition-gazebo-sensors-system.so" name="ignition::gazebo::systems::Sensors">
      <render_engine>ogre2</render_engine>
    </plugin>
  </gazebo>


  <gazebo reference="imu_link">
    <sensor name="imu_sensor" type="imu">
      <topic>/model/gz_example_robot/imu</topic>
      <frame_id>imu_link</frame_id>
      <ignition_frame_id>imu_link</ignition_frame_id>
      <plugin filename="libignition-gazebo-imu-system.so" name="ignition::gazebo::systems::Imu">
        <initial_orientation_as_reference>false</initial_orientation_as_reference>
      </plugin>
      <always_on>true</always_on>
      <update_rate>100</update_rate>
      <visualize>true</visualize>
     <imu>
     	<angular_velocity>
     	  <x>
     	    <noise type="gaussian">
              <mean>0.0</mean>
              <stddev>2e-4</stddev>
              <bias_mean>0.0000075</bias_mean>
              <bias_stddev>0.0000008</bias_stddev>
            </noise>
          </x>
          <y>
            <noise type="gaussian">
              <mean>0.0</mean>
              <stddev>2e-4</stddev>
              <bias_mean>0.0000075</bias_mean>
              <bias_stddev>0.0000008</bias_stddev>
            </noise>
          </y>
          <z>
            <noise type="gaussian">
              <mean>0.0</mean>
              <stddev>2e-4</stddev>
              <bias_mean>0.0000075</bias_mean>
              <bias_stddev>0.0000008</bias_stddev>
            </noise>
          </z>
        </angular_velocity>
        <linear_acceleration>
          <x>
            <noise type="gaussian">
              <mean>0.0</mean>
              <stddev>1.7e-2</stddev>
              <bias_mean>0.1</bias_mean>
              <bias_stddev>0.001</bias_stddev>
            </noise>
          </x>
          <y>
            <noise type="gaussian">
              <mean>0.0</mean>
              <stddev>1.7e-2</stddev>
              <bias_mean>0.1</bias_mean>
              <bias_stddev>0.001</bias_stddev>
            </noise>
          </y>
          <z>
            <noise type="gaussian">
              <mean>0.0</mean>
              <stddev>1.7e-2</stddev>
              <bias_mean>0.1</bias_mean>
              <bias_stddev>0.001</bias_stddev>
            </noise>
          </z>
        </linear_acceleration>
      </imu>
    </sensor>
  </gazebo>

  <gazebo reference="camera_link">
    <sensor type="depth" name="depth_camera_sensor">
      <camera name="head_camera">
        <horizontal_fov>${87*pi/180}</horizontal_fov>
        <vertical_fov>${58*pi/180}</vertical_fov>
        <image>
          <width>1280</width>
          <height>720</height>
        </image>
        <clip>
          <near>0.3</near>
          <far>4.0</far>
        </clip>
      </camera>
      <always_on>1</always_on>
      <update_rate>60</update_rate>
      <visualize>true</visualize>
      <topic>/model/yttrium/depth_camera</topic>
      <pose>0 0 0 1.5708 0 0</pose>
      <frame_id>depth</frame_id>
      <ignition_frame_id>depth</ignition_frame_id>
    </sensor>
      <plugin name="camera_plugin" filename="libgazebo_ros_openni_kinect.so">
        <alwaysOn>true</alwaysOn>
        <updateRate>60</updateRate>
        <cameraName>yttrium_camera</cameraName>
        <imageTopicName>/camera/color/image_raw</imageTopicName>
        <cameraInfoTopicName>/camera/color/camera_info</cameraInfoTopicName>
        <depthImageTopicName>/camera/depth/image_raw</depthImageTopicName>
        <depthImageCameraInfoTopicName>/camera/depth/camera_info</depthImageCameraInfoTopicName>
        <pointCloudTopicName>/camera/depth/points</pointCloudTopicName>
        <frameName>optical_link</frameName>
      </plugin>
  </gazebo>
</robot>
